{
    "registryname": "circuit_processor",
    "localizedname": "晶圆处理总成",
    "color":"ffffff",
    "parts": [
        {
            "x": -2,
            "y": 0,
            "z": 2,
            "elements": [
                "modularmachinery:blockcasing@0"
            ]
        },
        {
            "x": -1,
            "y": 2,
            "z": 3,
            "elements": [
                "modularmachinery:blockcasing@0"
            ]
        },
        {
            "x": -1,
            "y": 0,
            "z": 0,
            "elements": [
                "modularmachinery:blockcasing@0"
            ]
        },
        {
            "x": 1,
            "y": 2,
            "z": 1,
            "elements": [
                "modularmachinery:blockcasing@0"
            ]
        },
        {
            "x": -2,
            "y": 0,
            "z": 0,
            "elements": [
                "modularmachinery:blockcasing@4"
            ]
        },
        {
            "x": 0,
            "y": 2,
            "z": 3,
            "elements": [
                "modularmachinery:blockcasing@0"
            ]
        },
        {
            "x": 2,
            "y": 2,
            "z": 1,
            "elements": [
                "modularmachinery:blockcasing@0"
            ]
        },
        {
            "x": 1,
            "y": 0,
            "z": 0,
            "elements": [
                "modularmachinery:blockcasing@0"
            ]
        },
        {
            "x": -1,
            "y": 0,
            "z": 2,
            "elements": [
                "modularmachinery:blockcasing@0"
            ]
        },
        {
            "x": 0,
            "y": 0,
            "z": 2,
            "elements": [
                "modularmachinery:blockenergyinputhatch"
            ]
        },
        {
            "x": 2,
            "y": 0,
            "z": 0,
            "elements": [
                "modularmachinery:blockcasing@4"
            ]
        },
        {
            "x": -2,
            "y": 0,
            "z": 4,
            "elements": [
                "modularmachinery:blockcasing@4"
            ]
        },
        {
            "x": 1,
            "y": 2,
            "z": 3,
            "elements": [
                "modularmachinery:blockcasing@0"
            ]
        },
        {
            "x": 2,
            "y": 2,
            "z": 3,
            "elements": [
                "modularmachinery:blockcasing@0"
            ]
        },
        {
            "x": 1,
            "y": 0,
            "z": 2,
            "elements": [
                "modularmachinery:blockcasing@0"
            ]
        },
        {
            "x": -1,
            "y": 0,
            "z": 4,
            "elements": [
                "modularmachinery:blockcasing@0"
            ]
        },
        {
            "x": 2,
            "y": 0,
            "z": 2,
            "elements": [
                "modularmachinery:blockcasing@0"
            ]
        },
        {
            "x": 0,
            "y": 0,
            "z": 4,
            "elements": [
                "modularmachinery:blockfluidinputhatch"
            ]
        },
        {
            "x": 1,
            "y": 0,
            "z": 4,
            "elements": [
                "modularmachinery:blockcasing@0"
            ]
        },
        {
            "x": 2,
            "y": 0,
            "z": 4,
            "elements": [
                "modularmachinery:blockcasing@4"
            ]
        },
        {
            "x": -1,
            "y": 1,
            "z": 0,
            "elements": [
                "modularmachinery:blockcasing@5"
            ]
        },
        {
            "x": 0,
            "y": 1,
            "z": 0,
            "elements": [
                "modularmachinery:blockcasing@5"
            ]
        },
        {
            "x": -2,
            "y": 1,
            "z": 2,
            "elements": [
                "modularmachinery:blockfluidinputhatch"
            ]
        },
        {
            "x": -1,
            "y": 1,
            "z": 2,
            "elements": [
                "modularmachinery:blockcasing@3"
            ]
        },
        {
            "x": 1,
            "y": 1,
            "z": 0,
            "elements": [
                "modularmachinery:blockcasing@5"
            ]
        },
        {
            "x": 0,
            "y": 1,
            "z": 2,
            "elements": [
                "modularmachinery:blockcasing@3"
            ]
        },
        {
            "x": -1,
            "y": 1,
            "z": 4,
            "elements": [
                "modularmachinery:blockcasing@5"
            ]
        },
        {
            "x": 1,
            "y": 1,
            "z": 2,
            "elements": [
                "modularmachinery:blockcasing@3"
            ]
        },
        {
            "x": 0,
            "y": 1,
            "z": 4,
            "elements": [
                "modularmachinery:blockfluidinputhatch"
            ]
        },
        {
            "x": 2,
            "y": 1,
            "z": 2,
            "elements": [
                "modularmachinery:blockinputbus"
            ]
        },
        {
            "x": 1,
            "y": 1,
            "z": 4,
            "elements": [
                "modularmachinery:blockcasing@5"
            ]
        },
        {
            "x": -2,
            "y": 2,
            "z": 0,
            "elements": [
                "modularmachinery:blockcasing@4"
            ]
        },
        {
            "x": -1,
            "y": 2,
            "z": 0,
            "elements": [
                "modularmachinery:blockcasing@0"
            ]
        },
        {
            "x": 0,
            "y": 2,
            "z": 0,
            "elements": [
                "modularmachinery:blockcasing@0"
            ]
        },
        {
            "x": -2,
            "y": 2,
            "z": 2,
            "elements": [
                "modularmachinery:blockcasing@0"
            ]
        },
        {
            "x": -2,
            "y": 0,
            "z": 1,
            "elements": [
                "modularmachinery:blockcasing@2"
            ]
        },
        {
            "x": -1,
            "y": 2,
            "z": 2,
            "elements": [
                "modularmachinery:blockcasing@0"
            ]
        },
        {
            "x": 1,
            "y": 2,
            "z": 0,
            "elements": [
                "modularmachinery:blockcasing@0"
            ]
        },
        {
            "x": 0,
            "y": 2,
            "z": 2,
            "elements": [
                "modularmachinery:blockcasing@0"
            ]
        },
        {
            "x": 2,
            "y": 2,
            "z": 0,
            "elements": [
                "modularmachinery:blockcasing@4"
            ]
        },
        {
            "x": -1,
            "y": 0,
            "z": 1,
            "elements": [
                "modularmachinery:blockcasing@0"
            ]
        },
        {
            "x": -2,
            "y": 2,
            "z": 4,
            "elements": [
                "modularmachinery:blockcasing@4"
            ]
        },
        {
            "x": 0,
            "y": 0,
            "z": 1,
            "elements": [
                "modularmachinery:blockcasing@0"
            ]
        },
        {
            "x": -2,
            "y": 0,
            "z": 3,
            "elements": [
                "modularmachinery:blockcasing@0"
            ]
        },
        {
            "x": -1,
            "y": 2,
            "z": 4,
            "elements": [
                "modularmachinery:blockcasing@0"
            ]
        },
        {
            "x": 1,
            "y": 2,
            "z": 2,
            "elements": [
                "modularmachinery:blockcasing@0"
            ]
        },
        {
            "x": 0,
            "y": 2,
            "z": 4,
            "elements": [
                "modularmachinery:blockcasing@0"
            ]
        },
        {
            "x": 2,
            "y": 2,
            "z": 2,
            "elements": [
                "modularmachinery:blockcasing@0"
            ]
        },
        {
            "x": 1,
            "y": 0,
            "z": 1,
            "elements": [
                "modularmachinery:blockcasing@0"
            ]
        },
        {
            "x": -1,
            "y": 0,
            "z": 3,
            "elements": [
                "modularmachinery:blockcasing@0"
            ]
        },
        {
            "x": 2,
            "y": 0,
            "z": 1,
            "elements": [
                "modularmachinery:blockcasing@2"
            ]
        },
        {
            "x": 0,
            "y": 0,
            "z": 3,
            "elements": [
                "modularmachinery:blockcasing@0"
            ]
        },
        {
            "x": 1,
            "y": 2,
            "z": 4,
            "elements": [
                "modularmachinery:blockcasing@0"
            ]
        },
        {
            "x": 2,
            "y": 2,
            "z": 4,
            "elements": [
                "modularmachinery:blockcasing@4"
            ]
        },
        {
            "x": 1,
            "y": 0,
            "z": 3,
            "elements": [
                "modularmachinery:blockcasing@0"
            ]
        },
        {
            "x": 2,
            "y": 0,
            "z": 3,
            "elements": [
                "modularmachinery:blockcasing@0"
            ]
        },
        {
            "x": -2,
            "y": 1,
            "z": 1,
            "elements": [
                "modularmachinery:blockcasing@2"
            ]
        },
        {
            "x": -1,
            "y": 1,
            "z": 1,
            "elements": [
                "modularmachinery:blockcasing@2"
            ]
        },
        {
            "x": 0,
            "y": 1,
            "z": 1,
            "elements": [
                "modularmachinery:blockcasing@3"
            ]
        },
        {
            "x": -2,
            "y": 1,
            "z": 3,
            "elements": [
                "modularmachinery:blockfluidoutputhatch"
            ]
        },
        {
            "x": -1,
            "y": 1,
            "z": 3,
            "nbt": {"Type":"crafttweaker:chlorinizer"},
            "elements": [
                "extrautils2:machine@9"
            ]
        },
        {
            "x": 1,
            "y": 1,
            "z": 1,
            "elements": [
                "modularmachinery:blockcasing@2"
            ]
        },
        {
            "x": 0,
            "y": 1,
            "z": 3,
            "nbt": {"Type":"crafttweaker:silicon_grower"},
            "elements": [
                "extrautils2:machine@9"
            ]
        },
        {
            "x": 2,
            "y": 1,
            "z": 1,
            "elements": [
                "modularmachinery:blockcasing@2"
            ]
        },
        {
            "x": 1,
            "y": 1,
            "z": 3,
            "nbt": {"Type":"crafttweaker:polisher"},
            "elements": [
                "extrautils2:machine@9"
            ]
        },
        {
            "x": 2,
            "y": 1,
            "z": 3,
            "elements": [
                "modularmachinery:blockoutputbus"
            ]
        },
        {
            "x": -2,
            "y": 2,
            "z": 1,
            "elements": [
                "modularmachinery:blockcasing@0"
            ]
        },
        {
            "x": -1,
            "y": 2,
            "z": 1,
            "elements": [
                "modularmachinery:blockcasing@0"
            ]
        },
        {
            "x": 0,
            "y": 2,
            "z": 1,
            "elements": [
                "modularmachinery:blockcasing@0"
            ]
        },
        {
            "x": -2,
            "y": 2,
            "z": 3,
            "elements": [
                "modularmachinery:blockcasing@0"
            ]
        }
    ]}
