{
    "registryname": "intergrated_assembly_mk2",
    "localizedname": "集成装配机MK2",
    "requires-blueprint": true,
    "color":"2b2b2b",
    "parts": [
        {
            "x": -2,
            "y": -2,
            "z": -1,
            "elements": [
                "modularmachinery:blockcasing@4"
            ]
        },
        {
            "x": -1,
            "y": 0,
            "z": 0,
            "elements": [
                "extrautils2:decorativeglass@3"
            ]
        },
        {
            "x": -3,
            "y": -2,
            "z": -1,
            "elements": [
                "thermalfoundation:storage@6"
            ]
        },
        {
            "x": -2,
            "y": 0,
            "z": 0,
            "elements": [
                "extrautils2:decorativeglass@3"
            ]
        },
        {
            "x": 1,
            "y": 0,
            "z": 0,
            "elements": [
                "extrautils2:decorativeglass@3"
            ]
        },
        {
            "x": -3,
            "y": 0,
            "z": 0,
            "elements": [
                "extendedcrafting:trimmed@3"
            ]
        },
        {
            "x": 2,
            "y": 0,
            "z": 0,
            "elements": [
                "extrautils2:decorativeglass@3"
            ]
        },
        {
            "x": 3,
            "y": 0,
            "z": 0,
            "elements": [
                "extendedcrafting:trimmed@3"
            ]
        },
        {
            "x": 3,
            "y": 4,
            "z": -6,
            "elements": [
                "extendedcrafting:trimmed@3"
            ]
        },
        {
            "x": 2,
            "y": 4,
            "z": -6,
            "elements": [
                "extrautils2:decorativeglass@3"
            ]
        },
        {
            "x": 1,
            "y": 4,
            "z": -6,
            "elements": [
                "extrautils2:decorativeglass@3"
            ]
        },
        {
            "x": 0,
            "y": 4,
            "z": -6,
            "elements": [
                "extrautils2:decorativeglass@3"
            ]
        },
        {
            "x": -1,
            "y": 4,
            "z": -6,
            "elements": [
                "extrautils2:decorativeglass@3"
            ]
        },
        {
            "x": -2,
            "y": 4,
            "z": -6,
            "elements": [
                "extrautils2:decorativeglass@3"
            ]
        },
        {
            "x": -3,
            "y": 4,
            "z": -6,
            "elements": [
                "extendedcrafting:trimmed@3"
            ]
        },
        {
            "x": 3,
            "y": -1,
            "z": 0,
            "elements": [
                "actuallyadditions:block_crystal_empowered@4"
            ]
        },
        {
            "x": 2,
            "y": -1,
            "z": 0,
            "elements": [
                "actuallyadditions:block_crystal_empowered@4"
            ]
        },
        {
            "x": -3,
            "y": 1,
            "z": 0,
            "elements": [
                "extendedcrafting:trimmed@3"
            ]
        },
        {
            "x": 1,
            "y": -1,
            "z": 0,
            "elements": [
                "actuallyadditions:block_crystal_empowered@4"
            ]
        },
        {
            "x": -2,
            "y": 1,
            "z": 0,
            "elements": [
                "extrautils2:decorativeglass@3"
            ]
        },
        {
            "x": 0,
            "y": -1,
            "z": 0,
            "elements": [
                "modularmachinery:blockoutputbus@1"
            ]
        },
        {
            "x": -1,
            "y": 1,
            "z": 0,
            "elements": [
                "extrautils2:decorativeglass@3"
            ]
        },
        {
            "x": -1,
            "y": -1,
            "z": 0,
            "elements": [
                "actuallyadditions:block_crystal_empowered@4"
            ]
        },
        {
            "x": 0,
            "y": 1,
            "z": 0,
            "elements": [
                "extrautils2:decorativeglass@3"
            ]
        },
        {
            "x": -2,
            "y": -1,
            "z": 0,
            "elements": [
                "actuallyadditions:block_crystal_empowered@4"
            ]
        },
        {
            "x": 1,
            "y": 1,
            "z": 0,
            "elements": [
                "extrautils2:decorativeglass@3"
            ]
        },
        {
            "x": -3,
            "y": -1,
            "z": 0,
            "elements": [
                "actuallyadditions:block_crystal_empowered@4"
            ]
        },
        {
            "x": 2,
            "y": 1,
            "z": 0,
            "elements": [
                "extrautils2:decorativeglass@3"
            ]
        },
        {
            "x": 3,
            "y": 1,
            "z": 0,
            "elements": [
                "extendedcrafting:trimmed@3"
            ]
        },
        {
            "x": 3,
            "y": 3,
            "z": -6,
            "elements": [
                "extendedcrafting:trimmed@3"
            ]
        },
        {
            "x": 3,
            "y": 5,
            "z": -5,
            "elements": [
                "extendedcrafting:trimmed@3"
            ]
        },
        {
            "x": 2,
            "y": 3,
            "z": -6,
            "elements": [
                "extrautils2:decorativeglass@3"
            ]
        },
        {
            "x": 2,
            "y": 5,
            "z": -5,
            "elements": [
                "modularmachinery:blockcasing@1"
            ]
        },
        {
            "x": 1,
            "y": 3,
            "z": -6,
            "elements": [
                "extrautils2:decorativeglass@3"
            ]
        },
        {
            "x": 1,
            "y": 5,
            "z": -5,
            "elements": [
                "extendedcrafting:frame@0"
            ]
        },
        {
            "x": 0,
            "y": 3,
            "z": -6,
            "elements": [
                "extrautils2:decorativeglass@3"
            ]
        },
        {
            "x": 0,
            "y": 5,
            "z": -5,
            "elements": [
                "extendedcrafting:frame@0"
            ]
        },
        {
            "x": -1,
            "y": 3,
            "z": -6,
            "elements": [
                "extrautils2:decorativeglass@3"
            ]
        },
        {
            "x": -1,
            "y": 5,
            "z": -5,
            "elements": [
                "extendedcrafting:frame@0"
            ]
        },
        {
            "x": -2,
            "y": 3,
            "z": -6,
            "elements": [
                "extrautils2:decorativeglass@3"
            ]
        },
        {
            "x": -3,
            "y": 3,
            "z": -6,
            "elements": [
                "extendedcrafting:trimmed@3"
            ]
        },
        {
            "x": -2,
            "y": 5,
            "z": -5,
            "elements": [
                "modularmachinery:blockcasing@1"
            ]
        },
        {
            "x": -3,
            "y": 5,
            "z": -5,
            "elements": [
                "extendedcrafting:trimmed@3"
            ]
        },
        {
            "x": 3,
            "y": -2,
            "z": 0,
            "elements": [
                "thermalfoundation:storage@6"
            ]
        },
        {
            "x": 2,
            "y": -2,
            "z": 0,
            "elements": [
                "thermalfoundation:storage@6"
            ]
        },
        {
            "x": -3,
            "y": 2,
            "z": 0,
            "elements": [
                "extendedcrafting:trimmed@3"
            ]
        },
        {
            "x": 1,
            "y": -2,
            "z": 0,
            "elements": [
                "thermalfoundation:storage@6"
            ]
        },
        {
            "x": -2,
            "y": 2,
            "z": 0,
            "elements": [
                "extrautils2:decorativeglass@3"
            ]
        },
        {
            "x": 0,
            "y": -2,
            "z": 0,
            "elements": [
                "thermalfoundation:storage@6"
            ]
        },
        {
            "x": -1,
            "y": 2,
            "z": 0,
            "elements": [
                "extrautils2:decorativeglass@3"
            ]
        },
        {
            "x": -1,
            "y": -2,
            "z": 0,
            "elements": [
                "thermalfoundation:storage@6"
            ]
        },
        {
            "x": 0,
            "y": 2,
            "z": 0,
            "elements": [
                "extrautils2:decorativeglass@3"
            ]
        },
        {
            "x": -2,
            "y": -2,
            "z": 0,
            "elements": [
                "thermalfoundation:storage@6"
            ]
        },
        {
            "x": 1,
            "y": 2,
            "z": 0,
            "elements": [
                "extrautils2:decorativeglass@3"
            ]
        },
        {
            "x": -3,
            "y": -2,
            "z": 0,
            "elements": [
                "thermalfoundation:storage@6"
            ]
        },
        {
            "x": 2,
            "y": 2,
            "z": 0,
            "elements": [
                "extrautils2:decorativeglass@3"
            ]
        },
        {
            "x": 3,
            "y": 2,
            "z": 0,
            "elements": [
                "extendedcrafting:trimmed@3"
            ]
        },
        {
            "x": 3,
            "y": 2,
            "z": -6,
            "elements": [
                "extendedcrafting:trimmed@3"
            ]
        },
        {
            "x": 3,
            "y": 4,
            "z": -5,
            "elements": [
                "extrautils2:decorativeglass@3"
            ]
        },
        {
            "x": 2,
            "y": 2,
            "z": -6,
            "elements": [
                "extrautils2:decorativeglass@3"
            ]
        },
        {
            "x": 1,
            "y": 2,
            "z": -6,
            "elements": [
                "extrautils2:decorativeglass@3"
            ]
        },
        {
            "x": 0,
            "y": 2,
            "z": -6,
            "elements": [
                "extrautils2:decorativeglass@3"
            ]
        },
        {
            "x": -1,
            "y": 2,
            "z": -6,
            "elements": [
                "extrautils2:decorativeglass@3"
            ]
        },
        {
            "x": -2,
            "y": 2,
            "z": -6,
            "elements": [
                "extrautils2:decorativeglass@3"
            ]
        },
        {
            "x": -3,
            "y": 2,
            "z": -6,
            "elements": [
                "extendedcrafting:trimmed@3"
            ]
        },
        {
            "x": -3,
            "y": 4,
            "z": -5,
            "elements": [
                "extrautils2:decorativeglass@3"
            ]
        },
        {
            "x": -3,
            "y": 3,
            "z": 0,
            "elements": [
                "extendedcrafting:trimmed@3"
            ]
        },
        {
            "x": -2,
            "y": 3,
            "z": 0,
            "elements": [
                "extrautils2:decorativeglass@3"
            ]
        },
        {
            "x": -1,
            "y": 3,
            "z": 0,
            "elements": [
                "extrautils2:decorativeglass@3"
            ]
        },
        {
            "x": 0,
            "y": 3,
            "z": 0,
            "elements": [
                "extrautils2:decorativeglass@3"
            ]
        },
        {
            "x": 1,
            "y": 3,
            "z": 0,
            "elements": [
                "extrautils2:decorativeglass@3"
            ]
        },
        {
            "x": 2,
            "y": 3,
            "z": 0,
            "elements": [
                "extrautils2:decorativeglass@3"
            ]
        },
        {
            "x": 3,
            "y": 3,
            "z": 0,
            "elements": [
                "extendedcrafting:trimmed@3"
            ]
        },
        {
            "x": 3,
            "y": 1,
            "z": -6,
            "elements": [
                "extendedcrafting:trimmed@3"
            ]
        },
        {
            "x": 3,
            "y": 3,
            "z": -5,
            "elements": [
                "extrautils2:decorativeglass@3"
            ]
        },
        {
            "x": 2,
            "y": 1,
            "z": -6,
            "elements": [
                "extrautils2:decorativeglass@3"
            ]
        },
        {
            "x": 3,
            "y": 5,
            "z": -4,
            "elements": [
                "extendedcrafting:trimmed@3"
            ]
        },
        {
            "x": 1,
            "y": 1,
            "z": -6,
            "elements": [
                "extrautils2:decorativeglass@3"
            ]
        },
        {
            "x": 2,
            "y": 5,
            "z": -4,
            "elements": [
                "modularmachinery:blockcasing@1"
            ]
        },
        {
            "x": 0,
            "y": 1,
            "z": -6,
            "elements": [
                "extrautils2:decorativeglass@3"
            ]
        },
        {
            "x": 1,
            "y": 5,
            "z": -4,
            "elements": [
                "extendedcrafting:trimmed@3"
            ]
        },
        {
            "x": -1,
            "y": 1,
            "z": -6,
            "elements": [
                "extrautils2:decorativeglass@3"
            ]
        },
        {
            "x": -1,
            "y": 3,
            "z": -5,
            "elements": [
                "modularmachinery:blockcasing@5"
            ]
        },
        {
            "x": 0,
            "y": 5,
            "z": -4,
            "elements": [
                "extendedcrafting:trimmed@3"
            ]
        },
        {
            "x": -2,
            "y": 1,
            "z": -6,
            "elements": [
                "extrautils2:decorativeglass@3"
            ]
        },
        {
            "x": -3,
            "y": 1,
            "z": -6,
            "elements": [
                "extendedcrafting:trimmed@3"
            ]
        },
        {
            "x": -1,
            "y": 5,
            "z": -4,
            "elements": [
                "extendedcrafting:trimmed@3"
            ]
        },
        {
            "x": -2,
            "y": 5,
            "z": -4,
            "elements": [
                "modularmachinery:blockcasing@1"
            ]
        },
        {
            "x": -3,
            "y": 3,
            "z": -5,
            "elements": [
                "extrautils2:decorativeglass@3"
            ]
        },
        {
            "x": -3,
            "y": 5,
            "z": -4,
            "elements": [
                "extendedcrafting:trimmed@3"
            ]
        },
        {
            "x": -3,
            "y": 4,
            "z": 0,
            "elements": [
                "extendedcrafting:trimmed@3"
            ]
        },
        {
            "x": -2,
            "y": 4,
            "z": 0,
            "elements": [
                "extrautils2:decorativeglass@3"
            ]
        },
        {
            "x": -1,
            "y": 4,
            "z": 0,
            "elements": [
                "extrautils2:decorativeglass@3"
            ]
        },
        {
            "x": 0,
            "y": 4,
            "z": 0,
            "elements": [
                "extrautils2:decorativeglass@3"
            ]
        },
        {
            "x": 1,
            "y": 4,
            "z": 0,
            "elements": [
                "extrautils2:decorativeglass@3"
            ]
        },
        {
            "x": 2,
            "y": 4,
            "z": 0,
            "elements": [
                "extrautils2:decorativeglass@3"
            ]
        },
        {
            "x": 3,
            "y": 4,
            "z": 0,
            "elements": [
                "extendedcrafting:trimmed@3"
            ]
        },
        {
            "x": 3,
            "y": 0,
            "z": -6,
            "elements": [
                "extendedcrafting:trimmed@3"
            ]
        },
        {
            "x": 3,
            "y": 2,
            "z": -5,
            "elements": [
                "extrautils2:decorativeglass@3"
            ]
        },
        {
            "x": 2,
            "y": 0,
            "z": -6,
            "elements": [
                "extrautils2:decorativeglass@3"
            ]
        },
        {
            "x": 3,
            "y": 4,
            "z": -4,
            "elements": [
                "extrautils2:decorativeglass@3"
            ]
        },
        {
            "x": 1,
            "y": 0,
            "z": -6,
            "elements": [
                "extrautils2:decorativeglass@3"
            ]
        },
        {
            "x": 2,
            "y": 4,
            "z": -4,
            "elements": [
                "modularmachinery:blockcasing@1"
            ]
        },
        {
            "x": 0,
            "y": 0,
            "z": -6,
            "elements": [
                "extrautils2:decorativeglass@3"
            ]
        },
        {
            "x": -1,
            "y": 0,
            "z": -6,
            "elements": [
                "extrautils2:decorativeglass@3"
            ]
        },
        {
            "x": -2,
            "y": 0,
            "z": -6,
            "elements": [
                "extrautils2:decorativeglass@3"
            ]
        },
        {
            "x": -3,
            "y": 0,
            "z": -6,
            "elements": [
                "extendedcrafting:trimmed@3"
            ]
        },
        {
            "x": -3,
            "y": 2,
            "z": -5,
            "elements": [
                "extrautils2:decorativeglass@3"
            ]
        },
        {
            "x": -3,
            "y": 4,
            "z": -4,
            "elements": [
                "extrautils2:decorativeglass@3"
            ]
        },
        {
            "x": -3,
            "y": 5,
            "z": 0,
            "elements": [
                "extendedcrafting:trimmed@3"
            ]
        },
        {
            "x": -2,
            "y": 5,
            "z": 0,
            "elements": [
                "extendedcrafting:trimmed@3"
            ]
        },
        {
            "x": -1,
            "y": 5,
            "z": 0,
            "elements": [
                "extendedcrafting:trimmed@3"
            ]
        },
        {
            "x": 0,
            "y": 5,
            "z": 0,
            "elements": [
                "extendedcrafting:trimmed@3"
            ]
        },
        {
            "x": 1,
            "y": 5,
            "z": 0,
            "elements": [
                "extendedcrafting:trimmed@3"
            ]
        },
        {
            "x": 2,
            "y": 5,
            "z": 0,
            "elements": [
                "extendedcrafting:trimmed@3"
            ]
        },
        {
            "x": 3,
            "y": 5,
            "z": 0,
            "elements": [
                "extendedcrafting:trimmed@3"
            ]
        },
        {
            "x": 3,
            "y": -1,
            "z": -6,
            "elements": [
                "actuallyadditions:block_crystal_empowered@4"
            ]
        },
        {
            "x": 2,
            "y": -1,
            "z": -6,
            "elements": [
                "actuallyadditions:block_crystal_empowered@4"
            ]
        },
        {
            "x": 3,
            "y": 1,
            "z": -5,
            "elements": [
                "extrautils2:decorativeglass@3"
            ]
        },
        {
            "x": 1,
            "y": -1,
            "z": -6,
            "elements": [
                "actuallyadditions:block_crystal_empowered@4"
            ]
        },
        {
            "x": 3,
            "y": 3,
            "z": -4,
            "elements": [
                "extrautils2:decorativeglass@3"
            ]
        },
        {
            "x": 2,
            "y": 3,
            "z": -4,
            "elements": [
                "modularmachinery:blockcasing@1"
            ]
        },
        {
            "x": 0,
            "y": -1,
            "z": -6,
            "elements": [
                "modularmachinery:blockenergyinputhatch@3"
            ]
        },
        {
            "x": 3,
            "y": 5,
            "z": -3,
            "elements": [
                "extendedcrafting:trimmed@3"
            ]
        },
        {
            "x": -1,
            "y": -1,
            "z": -6,
            "elements": [
                "actuallyadditions:block_crystal_empowered@4"
            ]
        },
        {
            "x": 2,
            "y": 5,
            "z": -3,
            "elements": [
                "modularmachinery:blockcasing@1"
            ]
        },
        {
            "x": -2,
            "y": -1,
            "z": -6,
            "elements": [
                "actuallyadditions:block_crystal_empowered@4"
            ]
        },
        {
            "x": 1,
            "y": 5,
            "z": -3,
            "elements": [
                "modularmachinery:blockcasing@1"
            ]
        },
        {
            "x": -1,
            "y": 3,
            "z": -4,
            "elements": [
                "modularmachinery:blockcasing@3"
            ]
        },
        {
            "x": -3,
            "y": -1,
            "z": -6,
            "elements": [
                "actuallyadditions:block_crystal_empowered@4"
            ]
        },
        {
            "x": 0,
            "y": 5,
            "z": -3,
            "elements": [
                "modularmachinery:blockcasing@1"
            ]
        },
        {
            "x": -1,
            "y": 5,
            "z": -3,
            "elements": [
                "modularmachinery:blockcasing@1"
            ]
        },
        {
            "x": -3,
            "y": 1,
            "z": -5,
            "elements": [
                "extrautils2:decorativeglass@3"
            ]
        },
        {
            "x": -2,
            "y": 5,
            "z": -3,
            "elements": [
                "modularmachinery:blockcasing@1"
            ]
        },
        {
            "x": -3,
            "y": 3,
            "z": -4,
            "elements": [
                "extrautils2:decorativeglass@3"
            ]
        },
        {
            "x": -3,
            "y": 5,
            "z": -3,
            "elements": [
                "extendedcrafting:trimmed@3"
            ]
        },
        {
            "x": 3,
            "y": -2,
            "z": -6,
            "elements": [
                "thermalfoundation:storage@6"
            ]
        },
        {
            "x": 2,
            "y": -2,
            "z": -6,
            "elements": [
                "thermalfoundation:storage@6"
            ]
        },
        {
            "x": 3,
            "y": 0,
            "z": -5,
            "elements": [
                "extrautils2:decorativeglass@3"
            ]
        },
        {
            "x": 1,
            "y": -2,
            "z": -6,
            "elements": [
                "thermalfoundation:storage@6"
            ]
        },
        {
            "x": 2,
            "y": 0,
            "z": -5,
            "elements": [
                "embers:reactor@0"
            ]
        },
        {
            "x": 3,
            "y": 2,
            "z": -4,
            "elements": [
                "extrautils2:decorativeglass@3"
            ]
        },
        {
            "x": 0,
            "y": -2,
            "z": -6,
            "elements": [
                "thermalfoundation:storage@6"
            ]
        },
        {
            "x": 2,
            "y": 2,
            "z": -4,
            "elements": [
                "modularmachinery:blockcasing@1"
            ]
        },
        {
            "x": 3,
            "y": 4,
            "z": -3,
            "elements": [
                "extrautils2:decorativeglass@3"
            ]
        },
        {
            "x": -1,
            "y": -2,
            "z": -6,
            "elements": [
                "thermalfoundation:storage@6"
            ]
        },
        {
            "x": 1,
            "y": 2,
            "z": -4,
            "elements": [
                "modularmachinery:blockcasing@3"
            ]
        },
        {
            "x": -2,
            "y": -2,
            "z": -6,
            "elements": [
                "thermalfoundation:storage@6"
            ]
        },
        {
            "x": -3,
            "y": -2,
            "z": -6,
            "elements": [
                "thermalfoundation:storage@6"
            ]
        },
        {
            "x": -1,
            "y": 2,
            "z": -4,
            "elements": [
                "modularmachinery:blockcasing@4"
            ]
        },
        {
            "x": -2,
            "y": 0,
            "z": -5,
            "elements": [
                "modularmachinery:blockcasing@4"
            ]
        },
        {
            "x": -1,
            "y": 4,
            "z": -3,
            "elements": [
                "modularmachinery:blockcasing@1"
            ]
        },
        {
            "x": -3,
            "y": 0,
            "z": -5,
            "elements": [
                "extrautils2:decorativeglass@3"
            ]
        },
        {
            "x": -3,
            "y": 2,
            "z": -4,
            "elements": [
                "extrautils2:decorativeglass@3"
            ]
        },
        {
            "x": -3,
            "y": 4,
            "z": -3,
            "elements": [
                "extrautils2:decorativeglass@3"
            ]
        },
        {
            "x": 3,
            "y": -1,
            "z": -5,
            "elements": [
                "actuallyadditions:block_crystal_empowered@4"
            ]
        },
        {
            "x": 2,
            "y": -1,
            "z": -5,
            "elements": [
                "modularmachinery:blockcasing@5"
            ]
        },
        {
            "x": 3,
            "y": 1,
            "z": -4,
            "elements": [
                "extrautils2:decorativeglass@3"
            ]
        },
        {
            "x": 1,
            "y": -1,
            "z": -5,
            "elements": [
                "thermalfoundation:storage@7"
            ]
        },
        {
            "x": 3,
            "y": 3,
            "z": -3,
            "elements": [
                "extrautils2:decorativeglass@3"
            ]
        },
        {
            "x": 0,
            "y": -1,
            "z": -5,
            "elements": [
                "thermalfoundation:storage@7"
            ]
        },
        {
            "x": 1,
            "y": 1,
            "z": -4,
            "elements": [
                "immersiveengineering:metal_decoration1@4"
            ]
        },
        {
            "x": 3,
            "y": 5,
            "z": -2,
            "elements": [
                "extendedcrafting:trimmed@3"
            ]
        },
        {
            "x": -1,
            "y": -1,
            "z": -5,
            "elements": [
                "thermalfoundation:storage@7"
            ]
        },
        {
            "x": 2,
            "y": 5,
            "z": -2,
            "elements": [
                "modularmachinery:blockcasing@1"
            ]
        },
        {
            "x": -2,
            "y": -1,
            "z": -5,
            "elements": [
                "modularmachinery:blockcasing@5"
            ]
        },
        {
            "x": -1,
            "y": 1,
            "z": -4,
            "elements": [
                "modularmachinery:blockcasing@5"
            ]
        },
        {
            "x": 1,
            "y": 5,
            "z": -2,
            "elements": [
                "extendedcrafting:trimmed@3"
            ]
        },
        {
            "x": -1,
            "y": 3,
            "z": -3,
            "elements": [
                "modularmachinery:blockcasing@1"
            ]
        },
        {
            "x": -3,
            "y": -1,
            "z": -5,
            "elements": [
                "actuallyadditions:block_crystal_empowered@4"
            ]
        },
        {
            "x": 0,
            "y": 5,
            "z": -2,
            "elements": [
                "extendedcrafting:trimmed@3"
            ]
        },
        {
            "x": -1,
            "y": 5,
            "z": -2,
            "elements": [
                "extendedcrafting:trimmed@3"
            ]
        },
        {
            "x": -3,
            "y": 1,
            "z": -4,
            "elements": [
                "extrautils2:decorativeglass@3"
            ]
        },
        {
            "x": -2,
            "y": 5,
            "z": -2,
            "elements": [
                "modularmachinery:blockcasing@1"
            ]
        },
        {
            "x": -3,
            "y": 3,
            "z": -3,
            "elements": [
                "extrautils2:decorativeglass@3"
            ]
        },
        {
            "x": -3,
            "y": 5,
            "z": -2,
            "elements": [
                "extendedcrafting:trimmed@3"
            ]
        },
        {
            "x": 3,
            "y": -2,
            "z": -5,
            "elements": [
                "thermalfoundation:storage@6"
            ]
        },
        {
            "x": 2,
            "y": -2,
            "z": -5,
            "elements": [
                "modularmachinery:blockcasing@4"
            ]
        },
        {
            "x": 3,
            "y": 0,
            "z": -4,
            "elements": [
                "extrautils2:decorativeglass@3"
            ]
        },
        {
            "x": 1,
            "y": -2,
            "z": -5,
            "elements": [
                "modularmachinery:blockcasing@4"
            ]
        },
        {
            "x": 3,
            "y": 2,
            "z": -3,
            "elements": [
                "extrautils2:decorativeglass@3"
            ]
        },
        {
            "x": 0,
            "y": -2,
            "z": -5,
            "elements": [
                "modularmachinery:blockcasing@4"
            ]
        },
        {
            "x": 2,
            "y": 2,
            "z": -3,
            "elements": [
                "modularmachinery:blockcasing@3"
            ]
        },
        {
            "x": 1,
            "y": 0,
            "z": -4,
            "elements": [
                "immersiveengineering:metal_decoration1@4"
            ]
        },
        {
            "x": 3,
            "y": 4,
            "z": -2,
            "elements": [
                "extrautils2:decorativeglass@3"
            ]
        },
        {
            "x": -1,
            "y": -2,
            "z": -5,
            "elements": [
                "modularmachinery:blockcasing@4"
            ]
        },
        {
            "x": 2,
            "y": 4,
            "z": -2,
            "elements": [
                "modularmachinery:blockcasing@1"
            ]
        },
        {
            "x": -2,
            "y": -2,
            "z": -5,
            "elements": [
                "modularmachinery:blockcasing@4"
            ]
        },
        {
            "x": -1,
            "y": 0,
            "z": -4,
            "elements": [
                "modularmachinery:blockcasing@4"
            ]
        },
        {
            "x": -3,
            "y": -2,
            "z": -5,
            "elements": [
                "thermalfoundation:storage@6"
            ]
        },
        {
            "x": -2,
            "y": 0,
            "z": -4,
            "elements": [
                "modularmachinery:blockcasing@4"
            ]
        },
        {
            "x": -3,
            "y": 0,
            "z": -4,
            "elements": [
                "extrautils2:decorativeglass@3"
            ]
        },
        {
            "x": -3,
            "y": 2,
            "z": -3,
            "elements": [
                "extrautils2:decorativeglass@3"
            ]
        },
        {
            "x": -3,
            "y": 4,
            "z": -2,
            "elements": [
                "extrautils2:decorativeglass@3"
            ]
        },
        {
            "x": 3,
            "y": -1,
            "z": -4,
            "elements": [
                "actuallyadditions:block_crystal_empowered@4"
            ]
        },
        {
            "x": 2,
            "y": -1,
            "z": -4,
            "elements": [
                "thermalfoundation:storage@7"
            ]
        },
        {
            "x": 3,
            "y": 1,
            "z": -3,
            "elements": [
                "extrautils2:decorativeglass@3"
            ]
        },
        {
            "x": 1,
            "y": -1,
            "z": -4,
            "elements": [
                "thermalfoundation:storage@7"
            ]
        },
        {
            "x": 2,
            "y": 1,
            "z": -3,
            "elements": [
                "modularmachinery:blockcasing@5"
            ]
        },
        {
            "x": 3,
            "y": 3,
            "z": -2,
            "elements": [
                "extrautils2:decorativeglass@3"
            ]
        },
        {
            "x": 0,
            "y": -1,
            "z": -4,
            "elements": [
                "thermalfoundation:storage@7"
            ]
        },
        {
            "x": 2,
            "y": 3,
            "z": -2,
            "elements": [
                "modularmachinery:blockcasing@1"
            ]
        },
        {
            "x": 3,
            "y": 5,
            "z": -1,
            "elements": [
                "extendedcrafting:trimmed@3"
            ]
        },
        {
            "x": -1,
            "y": -1,
            "z": -4,
            "elements": [
                "modularmachinery:blockcasing@4"
            ]
        },
        {
            "x": 2,
            "y": 5,
            "z": -1,
            "elements": [
                "modularmachinery:blockcasing@1"
            ]
        },
        {
            "x": -2,
            "y": -1,
            "z": -4,
            "elements": [
                "thermalfoundation:storage@7"
            ]
        },
        {
            "x": 1,
            "y": 5,
            "z": -1,
            "elements": [
                "extendedcrafting:frame@0"
            ]
        },
        {
            "x": -1,
            "y": 3,
            "z": -2,
            "elements": [
                "modularmachinery:blockcasing@3"
            ]
        },
        {
            "x": -3,
            "y": -1,
            "z": -4,
            "elements": [
                "actuallyadditions:block_crystal_empowered@4"
            ]
        },
        {
            "x": 0,
            "y": 5,
            "z": -1,
            "elements": [
                "extendedcrafting:frame@0"
            ]
        },
        {
            "x": -1,
            "y": 5,
            "z": -1,
            "elements": [
                "extendedcrafting:frame@0"
            ]
        },
        {
            "x": -3,
            "y": 1,
            "z": -3,
            "elements": [
                "extrautils2:decorativeglass@3"
            ]
        },
        {
            "x": -2,
            "y": 5,
            "z": -1,
            "elements": [
                "modularmachinery:blockcasing@1"
            ]
        },
        {
            "x": -3,
            "y": 3,
            "z": -2,
            "elements": [
                "extrautils2:decorativeglass@3"
            ]
        },
        {
            "x": -3,
            "y": 5,
            "z": -1,
            "elements": [
                "extendedcrafting:trimmed@3"
            ]
        },
        {
            "x": 3,
            "y": -2,
            "z": -4,
            "elements": [
                "thermalfoundation:storage@6"
            ]
        },
        {
            "x": 2,
            "y": -2,
            "z": -4,
            "elements": [
                "modularmachinery:blockcasing@4"
            ]
        },
        {
            "x": 3,
            "y": 0,
            "z": -3,
            "elements": [
                "extrautils2:decorativeglass@3"
            ]
        },
        {
            "x": 1,
            "y": -2,
            "z": -4,
            "elements": [
                "thermalfoundation:storage@6"
            ]
        },
        {
            "x": 2,
            "y": 0,
            "z": -3,
            "elements": [
                "modularmachinery:blockcasing@4"
            ]
        },
        {
            "x": 3,
            "y": 2,
            "z": -2,
            "elements": [
                "extrautils2:decorativeglass@3"
            ]
        },
        {
            "x": 0,
            "y": -2,
            "z": -4,
            "elements": [
                "thermalfoundation:storage@6"
            ]
        },
        {
            "x": 2,
            "y": 2,
            "z": -2,
            "elements": [
                "modularmachinery:blockcasing@1"
            ]
        },
        {
            "x": 3,
            "y": 4,
            "z": -1,
            "elements": [
                "extrautils2:decorativeglass@3"
            ]
        },
        {
            "x": -1,
            "y": -2,
            "z": -4,
            "elements": [
                "modularmachinery:blockcasing@4"
            ]
        },
        {
            "x": 1,
            "y": 2,
            "z": -2,
            "elements": [
                "modularmachinery:blockcasing@3"
            ]
        },
        {
            "x": -2,
            "y": -2,
            "z": -4,
            "elements": [
                "thermalfoundation:storage@6"
            ]
        },
        {
            "x": -3,
            "y": -2,
            "z": -4,
            "elements": [
                "thermalfoundation:storage@6"
            ]
        },
        {
            "x": -1,
            "y": 2,
            "z": -2,
            "elements": [
                "embers:beam_cannon@0"
            ]
        },
        {
            "x": -3,
            "y": 0,
            "z": -3,
            "elements": [
                "extrautils2:decorativeglass@3"
            ]
        },
        {
            "x": -3,
            "y": 2,
            "z": -2,
            "elements": [
                "extrautils2:decorativeglass@3"
            ]
        },
        {
            "x": -3,
            "y": 4,
            "z": -1,
            "elements": [
                "extrautils2:decorativeglass@3"
            ]
        },
        {
            "x": 3,
            "y": -1,
            "z": -3,
            "elements": [
                "modularmachinery:blockinputbus@3"
            ]
        },
        {
            "x": 2,
            "y": -1,
            "z": -3,
            "elements": [
                "modularmachinery:blockcasing@4"
            ]
        },
        {
            "x": 3,
            "y": 1,
            "z": -2,
            "elements": [
                "extrautils2:decorativeglass@3"
            ]
        },
        {
            "x": 1,
            "y": -1,
            "z": -3,
            "elements": [
                "thermalfoundation:storage@7"
            ]
        },
        {
            "x": 3,
            "y": 3,
            "z": -1,
            "elements": [
                "extrautils2:decorativeglass@3"
            ]
        },
        {
            "x": 0,
            "y": -1,
            "z": -3,
            "elements": [
                "thermalfoundation:storage@7"
            ]
        },
        {
            "x": 1,
            "y": 1,
            "z": -2,
            "elements": [
                "embers:beam_cannon@0"
            ]
        },
        {
            "x": -1,
            "y": -1,
            "z": -3,
            "elements": [
                "thermalfoundation:storage@7"
            ]
        },
        {
            "x": -2,
            "y": -1,
            "z": -3,
            "elements": [
                "thermalfoundation:storage@7"
            ]
        },
        {
            "x": -1,
            "y": 1,
            "z": -2,
            "elements": [
                "enderio:block_end_iron_bars@0"
            ]
        },
        {
            "x": -3,
            "y": -1,
            "z": -3,
            "elements": [
                "modularmachinery:blockfluidinputhatch@3"
            ]
        },
        {
            "x": -3,
            "y": 1,
            "z": -2,
            "elements": [
                "extrautils2:decorativeglass@3"
            ]
        },
        {
            "x": -3,
            "y": 3,
            "z": -1,
            "elements": [
                "extrautils2:decorativeglass@3"
            ]
        },
        {
            "x": 3,
            "y": -2,
            "z": -3,
            "elements": [
                "thermalfoundation:storage@6"
            ]
        },
        {
            "x": 2,
            "y": -2,
            "z": -3,
            "elements": [
                "modularmachinery:blockcasing@4"
            ]
        },
        {
            "x": 3,
            "y": 0,
            "z": -2,
            "elements": [
                "extrautils2:decorativeglass@3"
            ]
        },
        {
            "x": 1,
            "y": -2,
            "z": -3,
            "elements": [
                "thermalfoundation:storage@6"
            ]
        },
        {
            "x": 3,
            "y": 2,
            "z": -1,
            "elements": [
                "extrautils2:decorativeglass@3"
            ]
        },
        {
            "x": 0,
            "y": -2,
            "z": -3,
            "elements": [
                "thermalfoundation:storage@6"
            ]
        },
        {
            "x": 1,
            "y": 0,
            "z": -2,
            "elements": [
                "enderio:block_dark_iron_bars@0"
            ]
        },
        {
            "x": -1,
            "y": -2,
            "z": -3,
            "elements": [
                "thermalfoundation:storage@6"
            ]
        },
        {
            "x": -2,
            "y": -2,
            "z": -3,
            "elements": [
                "thermalfoundation:storage@6"
            ]
        },
        {
            "x": -1,
            "y": 0,
            "z": -2,
            "elements": [
                "enderio:block_end_iron_bars@0"
            ]
        },
        {
            "x": -3,
            "y": -2,
            "z": -3,
            "elements": [
                "thermalfoundation:storage@6"
            ]
        },
        {
            "x": -3,
            "y": 0,
            "z": -2,
            "elements": [
                "extrautils2:decorativeglass@3"
            ]
        },
        {
            "x": -3,
            "y": 2,
            "z": -1,
            "elements": [
                "extrautils2:decorativeglass@3"
            ]
        },
        {
            "x": 3,
            "y": -1,
            "z": -2,
            "elements": [
                "actuallyadditions:block_crystal_empowered@4"
            ]
        },
        {
            "x": 2,
            "y": -1,
            "z": -2,
            "elements": [
                "thermalfoundation:storage@7"
            ]
        },
        {
            "x": 3,
            "y": 1,
            "z": -1,
            "elements": [
                "extrautils2:decorativeglass@3"
            ]
        },
        {
            "x": 1,
            "y": -1,
            "z": -2,
            "elements": [
                "thermalfoundation:storage@7"
            ]
        },
        {
            "x": 0,
            "y": -1,
            "z": -2,
            "elements": [
                "thermalfoundation:storage@7"
            ]
        },
        {
            "x": -1,
            "y": -1,
            "z": -2,
            "elements": [
                "thermalfoundation:storage@7"
            ]
        },
        {
            "x": -2,
            "y": -1,
            "z": -2,
            "elements": [
                "thermalfoundation:storage@7"
            ]
        },
        {
            "x": -3,
            "y": -1,
            "z": -2,
            "elements": [
                "actuallyadditions:block_crystal_empowered@4"
            ]
        },
        {
            "x": -3,
            "y": 1,
            "z": -1,
            "elements": [
                "extrautils2:decorativeglass@3"
            ]
        },
        {
            "x": 3,
            "y": -2,
            "z": -2,
            "elements": [
                "thermalfoundation:storage@6"
            ]
        },
        {
            "x": 2,
            "y": -2,
            "z": -2,
            "elements": [
                "modularmachinery:blockcasing@4"
            ]
        },
        {
            "x": 3,
            "y": 0,
            "z": -1,
            "elements": [
                "extrautils2:decorativeglass@3"
            ]
        },
        {
            "x": 1,
            "y": -2,
            "z": -2,
            "elements": [
                "thermalfoundation:storage@6"
            ]
        },
        {
            "x": 2,
            "y": 0,
            "z": -1,
            "elements": [
                "minecraft:sea_lantern@0"
            ]
        },
        {
            "x": 0,
            "y": -2,
            "z": -2,
            "elements": [
                "thermalfoundation:storage@6"
            ]
        },
        {
            "x": -1,
            "y": -2,
            "z": -2,
            "elements": [
                "thermalfoundation:storage@6"
            ]
        },
        {
            "x": -2,
            "y": -2,
            "z": -2,
            "elements": [
                "thermalfoundation:storage@6"
            ]
        },
        {
            "x": -3,
            "y": -2,
            "z": -2,
            "elements": [
                "thermalfoundation:storage@6"
            ]
        },
        {
            "x": -2,
            "y": 0,
            "z": -1,
            "elements": [
                "embers:cinder_plinth@0"
            ]
        },
        {
            "x": -3,
            "y": 0,
            "z": -1,
            "elements": [
                "extrautils2:decorativeglass@3"
            ]
        },
        {
            "x": 3,
            "y": -1,
            "z": -1,
            "elements": [
                "actuallyadditions:block_crystal_empowered@4"
            ]
        },
        {
            "x": 2,
            "y": -1,
            "z": -1,
            "elements": [
                "modularmachinery:blockcasing@5"
            ]
        },
        {
            "x": 1,
            "y": -1,
            "z": -1,
            "elements": [
                "thermalfoundation:storage@7"
            ]
        },
        {
            "x": 0,
            "y": -1,
            "z": -1,
            "elements": [
                "thermalfoundation:storage@7"
            ]
        },
        {
            "x": -1,
            "y": -1,
            "z": -1,
            "elements": [
                "thermalfoundation:storage@7"
            ]
        },
        {
            "x": -2,
            "y": -1,
            "z": -1,
            "elements": [
                "modularmachinery:blockcasing@5"
            ]
        },
        {
            "x": -3,
            "y": -1,
            "z": -1,
            "elements": [
                "actuallyadditions:block_crystal_empowered@4"
            ]
        },
        {
            "x": 3,
            "y": 5,
            "z": -6,
            "elements": [
                "extendedcrafting:trimmed@3"
            ]
        },
        {
            "x": 2,
            "y": 5,
            "z": -6,
            "elements": [
                "extendedcrafting:trimmed@3"
            ]
        },
        {
            "x": 1,
            "y": 5,
            "z": -6,
            "elements": [
                "extendedcrafting:trimmed@3"
            ]
        },
        {
            "x": 0,
            "y": 5,
            "z": -6,
            "elements": [
                "extendedcrafting:trimmed@3"
            ]
        },
        {
            "x": -1,
            "y": 5,
            "z": -6,
            "elements": [
                "extendedcrafting:trimmed@3"
            ]
        },
        {
            "x": -2,
            "y": 5,
            "z": -6,
            "elements": [
                "extendedcrafting:trimmed@3"
            ]
        },
        {
            "x": -3,
            "y": 5,
            "z": -6,
            "elements": [
                "extendedcrafting:trimmed@3"
            ]
        },
        {
            "x": 3,
            "y": -2,
            "z": -1,
            "elements": [
                "thermalfoundation:storage@6"
            ]
        },
        {
            "x": 2,
            "y": -2,
            "z": -1,
            "elements": [
                "modularmachinery:blockcasing@4"
            ]
        },
        {
            "x": 1,
            "y": -2,
            "z": -1,
            "elements": [
                "modularmachinery:blockcasing@4"
            ]
        },
        {
            "x": 0,
            "y": -2,
            "z": -1,
            "elements": [
                "modularmachinery:blockcasing@4"
            ]
        },
        {
            "x": -1,
            "y": -2,
            "z": -1,
            "elements": [
                "modularmachinery:blockcasing@4"
            ]
        }
    ]}