{
    "registryname": "steam_generator",
    "localizedname": "蒸汽涡轮机",
    "parts": [
        {
            "x": 0,
            "y": 4,
            "z": 4,
            "elements": [
                "thermalfoundation:storage_alloy@2"
            ]
        },
        {
            "x": -1,
            "y": 0,
            "z": 0,
            "elements": [
                "thermalfoundation:storage_alloy@3"
            ]
        },
        {
            "x": 1,
            "y": 2,
            "z": 1,
            "elements": [
                "minecraft:iron_block@0"
            ]
        },
        {
            "x": -1,
            "y": 2,
            "z": 3,
            "elements": [
                "minecraft:iron_block@0"
            ]
        },
        {
            "x": 1,
            "y": 4,
            "z": 4,
            "elements": [
                "thermalfoundation:storage_alloy@3"
            ]
        },
        {
            "x": 1,
            "y": 0,
            "z": 0,
            "elements": [
                "thermalfoundation:storage_alloy@3"
            ]
        },
        {
            "x": -1,
            "y": 0,
            "z": 2,
            "elements": [
                "minecraft:iron_block@0"
            ]
        },
        {
            "x": -1,
            "y": 2,
            "z": 5,
            "elements": [
                "thermalfoundation:storage_alloy@3"
            ]
        },
        {
            "x": 0,
            "y": 0,
            "z": 2,
            "nbt": {"casingColor":"16730368","ForgeCaps":{"nuclearcraft:capability_default_radiation_resistance":{"radiationResistance":"0.0d"}},"id":"minecraft:tilecolorablemachinecomponent"},
            "elements": [
                "modularmachinery:blockcasing@3"
            ]
        },
        {
            "x": 1,
            "y": 2,
            "z": 3,
            "elements": [
                "minecraft:iron_block@0"
            ]
        },
        {
            "x": 0,
            "y": 2,
            "z": 5,
            "elements": [
                "thermalfoundation:storage_alloy@2"
            ]
        },
        {
            "x": 1,
            "y": 0,
            "z": 2,
            "elements": [
                "minecraft:iron_block@0"
            ]
        },
        {
            "x": -1,
            "y": 0,
            "z": 4,
            "elements": [
                "minecraft:iron_block@0"
            ]
        },
        {
            "x": 1,
            "y": 2,
            "z": 5,
            "elements": [
                "thermalfoundation:storage_alloy@3"
            ]
        },
        {
            "x": 0,
            "y": 0,
            "z": 4,
            "nbt": {"casingColor":"16730368","ForgeCaps":{"nuclearcraft:capability_default_radiation_resistance":{"radiationResistance":"0.0d"}},"id":"minecraft:tilecolorablemachinecomponent"},
            "elements": [
                "modularmachinery:blockcasing@3"
            ]
        },
        {
            "x": 1,
            "y": 0,
            "z": 4,
            "elements": [
                "minecraft:iron_block@0"
            ]
        },
        {
            "x": 1,
            "y": -1,
            "z": 0,
            "elements": [
                "thermalfoundation:storage_alloy@3"
            ]
        },
        {
            "x": -1,
            "y": 3,
            "z": 1,
            "elements": [
                "minecraft:iron_block@0"
            ]
        },
        {
            "x": -1,
            "y": 1,
            "z": 0,
            "elements": [
                "thermalfoundation:storage_alloy@3"
            ]
        },
        {
            "x": 0,
            "y": -1,
            "z": 0,
            "nbt": {"input":"1b","size":"3","casingColor":"16730368","ForgeCaps":{"nuclearcraft:capability_default_radiation_resistance":{"radiationResistance":"0.0d"}},"id":"minecraft:tilefluidinputhatch","tank":{"Empty":"","gasTag":{"Empty":""}}},
            "elements": [
                "modularmachinery:blockfluidinputhatch@3"
            ]
        },
        {
            "x": 0,
            "y": 3,
            "z": 1,
            "nbt": {"casingColor":"16730368","ForgeCaps":{"nuclearcraft:capability_default_radiation_resistance":{"radiationResistance":"0.0d"}},"id":"minecraft:tilecolorablemachinecomponent"},
            "elements": [
                "modularmachinery:blockcasing@3"
            ]
        },
        {
            "x": 0,
            "y": 1,
            "z": 0,
            "elements": [
                "thermalfoundation:storage_alloy@2"
            ]
        },
        {
            "x": -1,
            "y": -1,
            "z": 0,
            "elements": [
                "thermalfoundation:storage_alloy@3"
            ]
        },
        {
            "x": 1,
            "y": 3,
            "z": 1,
            "elements": [
                "minecraft:iron_block@0"
            ]
        },
        {
            "x": -1,
            "y": 3,
            "z": 3,
            "elements": [
                "minecraft:iron_block@0"
            ]
        },
        {
            "x": 1,
            "y": 1,
            "z": 0,
            "elements": [
                "thermalfoundation:storage_alloy@3"
            ]
        },
        {
            "x": 0,
            "y": 3,
            "z": 3,
            "nbt": {"casingColor":"16730368","ForgeCaps":{"nuclearcraft:capability_default_radiation_resistance":{"radiationResistance":"0.0d"}},"id":"minecraft:tilecolorablemachinecomponent"},
            "elements": [
                "modularmachinery:blockcasing@3"
            ]
        },
        {
            "x": -1,
            "y": 1,
            "z": 2,
            "elements": [
                "minecraft:iron_block@0"
            ]
        },
        {
            "x": -1,
            "y": 3,
            "z": 5,
            "elements": [
                "thermalfoundation:storage_alloy@3"
            ]
        },
        {
            "x": -1,
            "y": -1,
            "z": 1,
            "elements": [
                "thermalfoundation:storage_alloy@3"
            ]
        },
        {
            "x": 1,
            "y": 3,
            "z": 3,
            "elements": [
                "minecraft:iron_block@0"
            ]
        },
        {
            "x": 0,
            "y": 3,
            "z": 5,
            "elements": [
                "thermalfoundation:storage_alloy@2"
            ]
        },
        {
            "x": 1,
            "y": 1,
            "z": 2,
            "elements": [
                "minecraft:iron_block@0"
            ]
        },
        {
            "x": 0,
            "y": -1,
            "z": 1,
            "elements": [
                "thermalfoundation:storage_alloy@2"
            ]
        },
        {
            "x": -1,
            "y": 1,
            "z": 4,
            "elements": [
                "minecraft:iron_block@0"
            ]
        },
        {
            "x": 1,
            "y": 3,
            "z": 5,
            "elements": [
                "thermalfoundation:storage_alloy@3"
            ]
        },
        {
            "x": -1,
            "y": -1,
            "z": 3,
            "elements": [
                "thermalfoundation:storage_alloy@3"
            ]
        },
        {
            "x": 0,
            "y": 1,
            "z": 4,
            "nbt": {"casingColor":"16730368","ForgeCaps":{"nuclearcraft:capability_default_radiation_resistance":{"radiationResistance":"0.0d"}},"id":"minecraft:tilecolorablemachinecomponent"},
            "elements": [
                "modularmachinery:blockcasing@3"
            ]
        },
        {
            "x": 1,
            "y": -1,
            "z": 1,
            "elements": [
                "thermalfoundation:storage_alloy@3"
            ]
        },
        {
            "x": 1,
            "y": 1,
            "z": 4,
            "elements": [
                "minecraft:iron_block@0"
            ]
        },
        {
            "x": 0,
            "y": -1,
            "z": 3,
            "elements": [
                "thermalfoundation:storage_alloy@2"
            ]
        },
        {
            "x": 1,
            "y": -1,
            "z": 3,
            "elements": [
                "thermalfoundation:storage_alloy@3"
            ]
        },
        {
            "x": -1,
            "y": 4,
            "z": 1,
            "elements": [
                "thermalfoundation:storage_alloy@3"
            ]
        },
        {
            "x": 0,
            "y": 4,
            "z": 1,
            "elements": [
                "thermalfoundation:storage_alloy@2"
            ]
        },
        {
            "x": -1,
            "y": 2,
            "z": 0,
            "elements": [
                "thermalfoundation:storage_alloy@3"
            ]
        },
        {
            "x": -1,
            "y": 4,
            "z": 3,
            "elements": [
                "thermalfoundation:storage_alloy@3"
            ]
        },
        {
            "x": 1,
            "y": 4,
            "z": 1,
            "elements": [
                "thermalfoundation:storage_alloy@3"
            ]
        },
        {
            "x": 0,
            "y": 2,
            "z": 0,
            "elements": [
                "thermalfoundation:storage_alloy@2"
            ]
        },
        {
            "x": 0,
            "y": 4,
            "z": 3,
            "nbt": {"input":"0b","size":"3","casingColor":"16730368","ForgeCaps":{"nuclearcraft:capability_default_radiation_resistance":{"radiationResistance":"0.0d"}},"id":"minecraft:tilefluidoutputhatch","tank":{"Empty":"","gasTag":{"Empty":""}}},
            "elements": [
                "modularmachinery:blockfluidoutputhatch@3"
            ]
        },
        {
            "x": 1,
            "y": 2,
            "z": 0,
            "elements": [
                "thermalfoundation:storage_alloy@3"
            ]
        },
        {
            "x": -1,
            "y": 2,
            "z": 2,
            "elements": [
                "minecraft:iron_block@0"
            ]
        },
        {
            "x": 1,
            "y": 4,
            "z": 3,
            "elements": [
                "thermalfoundation:storage_alloy@3"
            ]
        },
        {
            "x": -1,
            "y": 0,
            "z": 1,
            "elements": [
                "minecraft:iron_block@0"
            ]
        },
        {
            "x": 0,
            "y": 0,
            "z": 1,
            "nbt": {"casingColor":"16730368","ForgeCaps":{"nuclearcraft:capability_default_radiation_resistance":{"radiationResistance":"0.0d"}},"id":"minecraft:tilecolorablemachinecomponent"},
            "elements": [
                "modularmachinery:blockcasing@3"
            ]
        },
        {
            "x": 1,
            "y": 2,
            "z": 2,
            "elements": [
                "minecraft:iron_block@0"
            ]
        },
        {
            "x": -1,
            "y": 2,
            "z": 4,
            "elements": [
                "minecraft:iron_block@0"
            ]
        },
        {
            "x": 0,
            "y": 2,
            "z": 4,
            "nbt": {"casingColor":"16730368","ForgeCaps":{"nuclearcraft:capability_default_radiation_resistance":{"radiationResistance":"0.0d"}},"id":"minecraft:tilecolorablemachinecomponent"},
            "elements": [
                "modularmachinery:blockcasing@3"
            ]
        },
        {
            "x": 1,
            "y": 0,
            "z": 1,
            "elements": [
                "minecraft:iron_block@0"
            ]
        },
        {
            "x": -1,
            "y": 0,
            "z": 3,
            "elements": [
                "minecraft:iron_block@0"
            ]
        },
        {
            "x": 0,
            "y": 0,
            "z": 3,
            "nbt": {"casingColor":"16730368","ForgeCaps":{"nuclearcraft:capability_default_radiation_resistance":{"radiationResistance":"0.0d"}},"id":"minecraft:tilecolorablemachinecomponent"},
            "elements": [
                "modularmachinery:blockcasing@3"
            ]
        },
        {
            "x": 1,
            "y": 2,
            "z": 4,
            "elements": [
                "minecraft:iron_block@0"
            ]
        },
        {
            "x": -1,
            "y": 0,
            "z": 5,
            "elements": [
                "thermalfoundation:storage_alloy@3"
            ]
        },
        {
            "x": 1,
            "y": 0,
            "z": 3,
            "elements": [
                "minecraft:iron_block@0"
            ]
        },
        {
            "x": 0,
            "y": 0,
            "z": 5,
            "elements": [
                "thermalfoundation:storage_alloy@2"
            ]
        },
        {
            "x": 1,
            "y": 0,
            "z": 5,
            "elements": [
                "thermalfoundation:storage_alloy@3"
            ]
        },
        {
            "x": -1,
            "y": 3,
            "z": 0,
            "elements": [
                "thermalfoundation:storage_alloy@3"
            ]
        },
        {
            "x": 0,
            "y": 3,
            "z": 0,
            "elements": [
                "thermalfoundation:storage_alloy@2"
            ]
        },
        {
            "x": 1,
            "y": 3,
            "z": 0,
            "elements": [
                "thermalfoundation:storage_alloy@3"
            ]
        },
        {
            "x": -1,
            "y": 3,
            "z": 2,
            "elements": [
                "minecraft:iron_block@0"
            ]
        },
        {
            "x": 0,
            "y": 3,
            "z": 2,
            "nbt": {"casingColor":"16730368","ForgeCaps":{"nuclearcraft:capability_default_radiation_resistance":{"radiationResistance":"0.0d"}},"id":"minecraft:tilecolorablemachinecomponent"},
            "elements": [
                "modularmachinery:blockcasing@3"
            ]
        },
        {
            "x": -1,
            "y": 1,
            "z": 1,
            "elements": [
                "minecraft:iron_block@0"
            ]
        },
        {
            "x": 0,
            "y": 1,
            "z": 1,
            "nbt": {"casingColor":"16730368","ForgeCaps":{"nuclearcraft:capability_default_radiation_resistance":{"radiationResistance":"0.0d"}},"id":"minecraft:tilecolorablemachinecomponent"},
            "elements": [
                "modularmachinery:blockcasing@3"
            ]
        },
        {
            "x": 1,
            "y": 3,
            "z": 2,
            "elements": [
                "minecraft:iron_block@0"
            ]
        },
        {
            "x": -1,
            "y": 3,
            "z": 4,
            "elements": [
                "minecraft:iron_block@0"
            ]
        },
        {
            "x": 0,
            "y": 3,
            "z": 4,
            "nbt": {"casingColor":"16730368","ForgeCaps":{"nuclearcraft:capability_default_radiation_resistance":{"radiationResistance":"0.0d"}},"id":"minecraft:tilecolorablemachinecomponent"},
            "elements": [
                "modularmachinery:blockcasing@3"
            ]
        },
        {
            "x": 1,
            "y": 1,
            "z": 1,
            "elements": [
                "minecraft:iron_block@0"
            ]
        },
        {
            "x": -1,
            "y": 1,
            "z": 3,
            "elements": [
                "minecraft:iron_block@0"
            ]
        },
        {
            "x": -1,
            "y": -1,
            "z": 2,
            "elements": [
                "thermalfoundation:storage_alloy@3"
            ]
        },
        {
            "x": 1,
            "y": 3,
            "z": 4,
            "elements": [
                "minecraft:iron_block@0"
            ]
        },
        {
            "x": -1,
            "y": 1,
            "z": 5,
            "elements": [
                "thermalfoundation:storage_alloy@3"
            ]
        },
        {
            "x": 1,
            "y": 1,
            "z": 3,
            "elements": [
                "minecraft:iron_block@0"
            ]
        },
        {
            "x": 0,
            "y": -1,
            "z": 2,
            "elements": [
                "thermalfoundation:storage_alloy@2"
            ]
        },
        {
            "x": 0,
            "y": 1,
            "z": 5,
            "nbt": {"hatchSize":"3","casingColor":"16730368","ForgeCaps":{"nuclearcraft:capability_default_radiation_resistance":{"radiationResistance":"0.0d"}},"id":"minecraft:tileenergyoutputhatch","energy":"0L"},
            "elements": [
                "modularmachinery:blockenergyoutputhatch@3"
            ]
        },
        {
            "x": -1,
            "y": -1,
            "z": 4,
            "elements": [
                "thermalfoundation:storage_alloy@3"
            ]
        },
        {
            "x": 1,
            "y": -1,
            "z": 2,
            "elements": [
                "thermalfoundation:storage_alloy@3"
            ]
        },
        {
            "x": 1,
            "y": 1,
            "z": 5,
            "elements": [
                "thermalfoundation:storage_alloy@3"
            ]
        },
        {
            "x": 0,
            "y": -1,
            "z": 4,
            "elements": [
                "thermalfoundation:storage_alloy@2"
            ]
        },
        {
            "x": 1,
            "y": -1,
            "z": 4,
            "elements": [
                "thermalfoundation:storage_alloy@3"
            ]
        },
        {
            "x": -1,
            "y": 4,
            "z": 2,
            "elements": [
                "thermalfoundation:storage_alloy@3"
            ]
        },
        {
            "x": 0,
            "y": 4,
            "z": 2,
            "elements": [
                "thermalfoundation:storage_alloy@2"
            ]
        },
        {
            "x": -1,
            "y": 2,
            "z": 1,
            "elements": [
                "minecraft:iron_block@0"
            ]
        },
        {
            "x": -1,
            "y": 4,
            "z": 4,
            "elements": [
                "thermalfoundation:storage_alloy@3"
            ]
        },
        {
            "x": 1,
            "y": 4,
            "z": 2,
            "elements": [
                "thermalfoundation:storage_alloy@3"
            ]
        },
        {
            "x": 0,
            "y": 2,
            "z": 1,
            "nbt": {"casingColor":"16730368","ForgeCaps":{"nuclearcraft:capability_default_radiation_resistance":{"radiationResistance":"0.0d"}},"id":"minecraft:tilecolorablemachinecomponent"},
            "elements": [
                "modularmachinery:blockcasing@3"
            ]
        }
    ]}