
# Created by Ruins mod version 17.2 Ingame Parser
# authoring Player: Mc_EeL

# TEMPLATE PARAMETER SETTINGS:
#
# criterion expression specifying mod ids required to load template
# may include plus (AND), minus (AND NOT), comma (OR), and parentheses
# all required mods listed must be present; no prohibited mods can be
requiredMods=
#
# likelihood this template will be chosen relative to all others
# e.g., a weight=6 template is chosen 3X as often as one with weight=2
weight=0.1
#
# list of dimensions in which this template may spawn, even if generic
# one or more dimension names, separated by commas (blank = all)
dimensionsToSpawnIn=overworld
#
# list of other biomes in which this template may spawn
# biome corresponding to directory is always assumed, listed or not
# generic templates should leave this list empty
biomesToSpawnIn=
#
# criterion expression specifying types of biome where template spawns
# this is in addition to those explicitly listed as biomesToSpawnIn
# generic templates should leave this list empty
biomeTypesToSpawnIn=
#
# list of biomes in which this template may not spawn
# takes precedence over biomeTypesToSpawnIn, but NOT biomesToSpawnIn
# should be empty if biomeTypesToSpawnIn is empty
biomesToNotSpawnIn=
#
# depth template is pushed down into the surface when built
# offset is min/max range of random additional bury depth
embed_into_distance=14
random_height_offset=0,0
#
# whitelist/blacklist of block types on which template may be built
# specify one, not both; leave the other empty (both empty = allow all)
acceptable_target_blocks=
unacceptable_target_blocks=flowing_water,water,flowing_lava,lava
#
# size of template (#layers, #rows per layer, #blocks per row)
dimensions=19,11,16
#
# max number of missing blocks allowed in surface beneath template
allowable_overhang=0
#
# depth/height limit affected by terrain leveling
# also maximum bumpiness tolerated in surface beneath template
max_leveling=2
#
# padding applied to all sides of template horizontal footprint
# expands area affected by terrain leveling (-1 = no leveling)
leveling_buffer=0
#
# do not rotate template randomly when built (1 = no rotation)
preventRotation=0
#
# treat water/lava blocks as air and protect them from rule0 (1 = yes)
preserve_water=0
preserve_lava=0
#
# minimum distance this template must have from instances of itself
uniqueMinDistance=0
#
# min/max distances this template can be from world spawn (0 = no limit)
# only applies to overworld--i.e., dimension 0
spawnMinDistance=0
spawnMaxDistance=0
#
# other template built nearby whenever this one is
# syntax: <name>;<relativeX>;<maxYdifference>;<relativeZ>[;<chance>]
# may be used more than once to specify multiple neighbors
adjoining_template=

rule1=0,100,minecraft:obsidian-0
rule2=0,100,appliedenergistics2:quartz_growth_accelerator-0,minecraft:obsidian-0
rule3=0,100,contenttweaker:paper-0,minecraft:preserveBlock
rule4=0,100,minecraft:jukebox-0,minecraft:preserveBlock
rule5=0,100,appliedenergistics2:spatial_io_port-0,minecraft:preserveBlock
rule6=0,100,appliedenergistics2:cell_workbench-0,minecraft:preserveBlock
rule7=0,100,appliedenergistics2:crafting_storage_1k-2,minecraft:preserveBlock
rule8=0,100,minecraft:bed-10
rule9=0,100,minecraft:bed-2
rule10=0,100,minecraft:stone_slab-8
rule11=0,100,contenttweaker:crystal-0,minecraft:preserveBlock
rule12=0,100,contenttweaker:philosophers_sand-0,minecraft:preserveBlock
rule13=0,100,minecraft:nether_brick_fence-0
rule14=0,100,minecraft:dark_oak_fence_gate-3
rule15=0,100,minecraft:water-0
rule16=0,100,minecraft:end_rod-1
rule17=0,100,minecraft:sea_lantern-0
rule18=0,100,minecraft:dirt-0
rule19=0,100,minecraft:stone_stairs-0
rule20=0,100,minecraft:cobblestone-0
rule21=0,100,minecraft:planks-0
rule22=0,100,minecraft:iron_trapdoor-9
rule23=0,100,minecraft:iron_door-0
rule24=0,100,minecraft:ladder-5
rule25=0,100,minecraft:iron_door-9
rule26=0,100,minecraft:log-0
rule27=0,100,minecraft:fence-0
rule28=0,100,minecraft:preserveBlock

layer
28,28,28,28,28,28,28,28,28,28,28,28,28,28,28,28
28,28,28,28,28,28,28,28,28,28,28,28,28,28,28,28
1,1,1,1,1,1,1,1,1,1,1,1,1,28,28,28
1,1,1,1,1,1,1,1,1,1,1,1,1,28,28,28
1,1,1,1,1,1,1,1,1,1,1,1,1,28,28,28
1,1,1,1,1,1,1,1,1,1,1,1,1,28,28,28
1,1,1,1,1,1,1,1,1,1,1,1,1,28,28,28
1,1,1,1,1,1,1,1,1,1,1,1,1,28,28,28
1,1,2,2,2,2,2,1,1,1,1,1,1,28,28,28
1,1,1,1,1,1,1,1,1,1,1,1,1,28,28,28
28,28,28,28,28,28,28,28,28,28,28,28,28,28,28,28
endlayer

layer
28,28,28,28,28,28,28,28,28,28,28,28,28,28,28,28
28,28,28,28,28,28,28,28,28,28,28,28,28,28,28,28
1,1,1,1,1,1,1,1,1,1,1,1,1,28,28,28
1,3,7,3,6,5,0,0,0,0,4,3,1,28,28,28
1,0,0,0,0,0,0,0,0,0,9,8,1,28,28,28
1,0,0,0,0,0,0,0,0,0,0,10,1,28,28,28
1,0,0,0,0,0,0,0,0,0,0,0,1,28,28,28
1,13,13,13,14,13,13,13,0,12,11,0,1,28,28,28
1,13,15,15,15,15,15,12,12,12,12,11,1,28,28,28
1,1,1,1,1,1,1,1,1,1,1,1,1,28,28,28
28,28,28,28,28,28,28,28,28,28,28,28,28,28,28,28
endlayer

layer
28,28,28,28,28,28,28,28,28,28,28,28,28,28,28,28
28,28,28,28,28,28,28,28,28,28,28,28,28,28,28,28
1,1,1,1,1,1,1,1,1,1,1,1,1,28,28,28
1,0,7,0,0,0,0,0,0,0,0,0,1,28,28,28
1,0,0,0,0,0,0,0,0,0,0,0,1,28,28,28
1,0,0,0,0,0,0,0,0,0,0,16,1,28,28,28
1,0,0,0,0,0,0,0,0,0,0,0,1,28,28,28
1,0,0,0,0,0,0,0,0,0,0,0,1,28,28,28
1,0,0,0,0,0,0,0,12,12,0,0,1,28,28,28
1,1,1,1,1,1,1,1,1,1,1,1,1,28,28,28
28,28,28,28,28,28,28,28,28,28,28,28,28,28,28,28
endlayer

layer
28,28,28,28,28,28,28,28,28,28,28,28,28,28,28,28
28,28,28,28,28,28,28,28,28,28,28,28,28,28,28,28
1,1,1,1,1,1,1,1,1,1,1,1,1,28,28,28
1,17,0,0,0,0,0,0,0,0,0,17,1,28,28,28
1,0,0,0,0,0,0,0,0,0,0,0,1,28,28,28
1,0,0,0,0,0,0,0,0,0,0,0,1,28,28,28
1,0,0,0,0,0,0,0,0,0,0,0,1,28,28,28
1,0,0,0,0,0,0,0,0,0,0,0,1,28,28,28
1,17,0,0,0,0,0,0,11,0,0,17,1,28,28,28
1,1,1,1,1,1,1,1,1,1,1,1,1,28,28,28
28,28,28,28,28,28,28,28,28,28,28,28,28,28,28,28
endlayer

layer
28,28,28,28,28,28,28,28,28,28,28,28,28,28,28,28
28,28,28,28,28,28,28,28,28,28,28,28,28,28,28,28
1,1,1,1,1,1,1,1,1,1,1,1,1,28,28,28
1,1,1,1,1,1,1,1,1,1,1,1,1,28,28,28
1,1,1,1,1,1,1,1,1,1,1,1,1,28,28,28
1,1,1,1,1,1,1,0,1,1,1,1,1,28,28,28
1,1,1,1,1,1,1,1,1,1,1,1,1,28,28,28
1,1,1,1,1,1,1,1,1,1,1,1,1,28,28,28
1,1,1,1,1,1,1,1,1,1,1,1,1,28,28,28
1,1,1,1,1,1,1,1,1,1,1,1,1,28,28,28
28,28,28,28,28,28,28,28,28,28,28,28,28,28,28,28
endlayer

layer
28,28,28,28,28,28,28,28,28,28,28,28,28,28,28,28
28,28,28,28,28,28,28,28,28,28,28,28,28,28,28,28
28,28,28,28,28,28,28,28,28,28,28,28,28,28,28,28
28,28,28,28,28,28,28,28,28,28,28,28,28,28,28,28
28,28,28,28,28,28,1,1,1,28,28,28,28,28,28,28
28,28,28,28,28,28,1,0,1,28,28,28,28,28,28,28
28,28,28,28,28,28,1,1,1,28,28,28,28,28,28,28
28,28,28,28,28,28,28,28,28,28,28,28,28,28,28,28
28,28,28,28,28,28,28,28,28,28,28,28,28,28,28,28
28,28,28,28,28,28,28,28,28,28,28,28,28,28,28,28
28,28,28,28,28,28,28,28,28,28,28,28,28,28,28,28
endlayer

layer
28,28,28,28,28,28,28,28,28,28,28,28,28,28,28,28
28,28,28,28,28,28,28,28,28,28,28,28,28,28,28,28
28,28,28,28,28,28,28,28,28,28,28,28,28,28,28,28
28,28,28,28,28,28,28,28,28,28,28,28,28,28,28,28
28,28,28,28,28,28,1,1,1,28,28,28,28,28,28,28
28,28,28,28,28,28,1,0,1,28,28,28,28,28,28,28
28,28,28,28,28,28,1,1,1,28,28,28,28,28,28,28
28,28,28,28,28,28,28,28,28,28,28,28,28,28,28,28
28,28,28,28,28,28,28,28,28,28,28,28,28,28,28,28
28,28,28,28,28,28,28,28,28,28,28,28,28,28,28,28
28,28,28,28,28,28,28,28,28,28,28,28,28,28,28,28
endlayer

layer
28,28,28,28,28,28,28,28,28,28,28,28,28,28,28,28
28,28,28,28,28,28,28,28,28,28,28,28,28,28,28,28
28,28,28,28,28,28,28,28,28,28,28,28,28,28,28,28
28,28,28,28,28,28,28,28,28,28,28,28,28,28,28,28
28,28,28,28,28,28,1,1,1,28,28,28,28,28,28,28
28,28,28,28,28,28,1,0,1,28,28,28,28,28,28,28
28,28,28,28,28,28,1,1,1,28,28,28,28,28,28,28
28,28,28,28,28,28,28,28,28,28,28,28,28,28,28,28
28,28,28,28,28,28,28,28,28,28,28,28,28,28,28,28
28,28,28,28,28,28,28,28,28,28,28,28,28,28,28,28
28,28,28,28,28,28,28,28,28,28,28,28,28,28,28,28
endlayer

layer
28,28,28,28,28,28,28,28,28,28,28,28,28,28,28,28
28,28,28,28,28,28,28,28,28,28,28,28,28,28,28,28
28,28,28,28,28,28,28,28,28,28,28,28,28,28,28,28
28,28,28,28,28,28,28,28,28,28,28,28,28,28,28,28
28,28,28,28,28,28,1,1,1,28,28,28,28,28,28,28
28,28,28,28,28,28,1,0,1,28,28,28,28,28,28,28
28,28,28,28,28,28,1,1,1,28,28,28,28,28,28,28
28,28,28,28,28,28,28,28,28,28,28,28,28,28,28,28
28,28,28,28,28,28,28,28,28,28,28,28,28,28,28,28
28,28,28,28,28,28,28,28,28,28,28,28,28,28,28,28
28,28,28,28,28,28,28,28,28,28,28,28,28,28,28,28
endlayer

layer
28,28,28,28,28,28,28,28,28,28,28,28,28,28,28,28
28,28,28,28,28,28,28,28,28,28,28,28,28,28,28,28
28,28,28,28,28,28,28,28,28,28,28,28,28,28,28,28
28,28,28,28,28,28,28,28,28,28,28,28,28,28,28,28
28,28,28,28,28,28,1,1,1,28,28,28,28,28,28,28
28,28,28,28,28,28,1,0,1,28,28,28,28,28,28,28
28,28,28,28,28,28,1,1,1,28,28,28,28,28,28,28
28,28,28,28,28,28,28,28,28,28,28,28,28,28,28,28
28,28,28,28,28,28,28,28,28,28,28,28,28,28,28,28
28,28,28,28,28,28,28,28,28,28,28,28,28,28,28,28
28,28,28,28,28,28,28,28,28,28,28,28,28,28,28,28
endlayer

layer
28,28,28,28,28,28,28,28,28,28,28,28,28,28,28,28
28,28,28,28,28,28,28,28,28,28,28,28,28,28,28,28
28,28,28,28,28,28,28,28,28,28,28,28,28,28,28,28
28,28,28,28,28,28,28,28,28,28,28,28,28,28,28,28
28,28,28,28,28,28,1,1,1,28,28,28,28,28,28,28
28,28,28,28,28,28,1,0,1,28,28,28,28,28,28,28
28,28,28,28,28,28,1,1,1,28,28,28,28,28,28,28
28,28,28,28,28,28,28,28,28,28,28,28,28,28,28,28
28,28,28,28,28,28,28,28,28,28,28,28,28,28,28,28
28,28,28,28,28,28,28,28,28,28,28,28,28,28,28,28
28,28,28,28,28,28,28,28,28,28,28,28,28,28,28,28
endlayer

layer
28,28,28,28,28,28,28,28,28,28,28,28,28,28,28,28
28,28,28,28,28,28,28,28,28,28,28,28,28,28,28,28
28,28,28,28,28,28,28,28,28,28,28,28,28,28,28,28
28,28,28,28,28,28,28,28,28,28,28,28,28,28,28,28
28,28,28,28,28,28,1,1,1,28,28,28,28,28,28,28
28,28,28,28,28,28,1,0,1,28,28,28,28,28,28,28
28,28,28,28,28,28,1,1,1,28,28,28,28,28,28,28
28,28,28,28,28,28,28,28,28,28,28,28,28,28,28,28
28,28,28,28,28,28,28,28,28,28,28,28,28,28,28,28
28,28,28,28,28,28,28,28,28,28,28,28,28,28,28,28
28,28,28,28,28,28,28,28,28,28,28,28,28,28,28,28
endlayer

layer
28,28,28,28,28,28,28,28,28,28,28,28,28,28,28,28
28,28,28,28,28,28,28,28,28,28,28,28,28,28,28,28
28,28,28,18,18,18,18,18,18,18,18,28,28,28,28,28
28,28,28,18,18,18,18,18,18,18,18,28,28,28,28,28
28,28,28,18,18,18,18,18,18,18,18,28,28,28,28,28
28,28,28,18,18,18,18,0,18,18,18,28,28,28,28,28
28,28,28,18,18,18,18,18,18,18,18,28,28,28,28,28
28,28,28,18,18,18,18,18,18,18,18,28,28,28,28,28
28,28,28,18,18,18,18,18,18,18,18,28,28,28,28,28
28,28,28,28,28,28,28,28,28,28,28,28,28,28,28,28
28,28,28,28,28,28,28,28,28,28,28,28,28,28,28,28
endlayer

layer
28,28,28,28,28,28,28,28,28,28,28,28,28,28,28,28
28,28,28,28,28,28,28,28,28,28,28,28,28,28,28,28
28,28,28,18,18,18,18,18,18,18,18,28,28,28,28,28
28,28,28,18,18,18,18,18,18,18,18,28,28,28,28,28
28,28,28,18,18,18,18,18,18,18,18,28,28,28,28,28
28,28,28,18,18,18,18,0,18,18,18,28,28,28,28,28
28,28,28,18,18,18,18,18,18,18,18,28,28,28,28,28
28,28,28,18,18,18,18,18,18,18,18,28,28,28,28,28
28,28,28,18,18,18,18,18,18,18,18,28,28,28,28,28
28,28,28,28,28,28,28,28,28,28,28,28,28,28,28,28
28,28,28,28,28,28,28,28,28,28,28,28,28,28,28,28
endlayer

layer
28,28,28,28,28,28,28,28,28,28,28,28,28,28,28,28
28,28,28,28,28,28,28,28,19,28,28,28,28,28,28,28
28,28,28,20,20,20,20,20,21,20,20,28,28,28,28,28
28,28,28,20,21,21,21,21,21,21,20,28,28,28,28,28
28,28,28,20,21,21,21,21,21,21,20,28,28,28,28,28
28,28,28,20,21,21,21,22,21,21,20,28,28,28,28,28
28,28,28,20,21,21,21,21,21,21,20,28,28,28,28,28
28,28,28,20,21,21,21,21,21,21,20,28,28,28,28,28
28,28,28,20,20,20,20,20,20,20,20,28,28,28,28,28
28,28,28,28,28,28,28,28,28,28,28,28,28,28,28,28
28,28,28,28,28,28,28,28,28,28,28,28,28,28,28,28
endlayer

layer
28,28,28,28,28,28,28,28,28,28,28,28,28,28,28,28
28,28,28,28,28,28,28,28,28,28,28,28,28,28,28,28
28,28,28,20,21,21,21,21,23,21,20,28,28,28,28,28
28,28,28,21,0,24,0,0,0,0,21,28,28,28,28,28
28,28,28,21,0,0,0,0,0,0,21,28,28,28,28,28
28,28,28,21,0,0,0,0,0,0,21,28,28,28,28,28
28,28,28,21,0,0,0,0,0,0,21,28,28,28,28,28
28,28,28,21,0,0,0,0,0,0,21,28,28,28,28,28
28,28,28,20,21,21,21,21,21,21,20,28,28,28,28,28
28,28,28,28,28,28,28,28,28,28,28,28,28,28,28,28
28,28,28,28,28,28,28,28,28,28,28,28,28,28,28,28
endlayer

layer
28,28,28,28,28,28,28,28,28,28,28,28,28,28,28,28
28,28,28,28,28,28,28,28,28,28,28,28,28,28,28,28
28,28,28,20,21,21,21,21,25,21,20,28,28,28,28,28
28,28,28,21,0,24,0,0,0,0,21,28,28,28,28,28
28,28,28,21,0,0,0,0,0,0,21,28,28,28,28,28
28,28,28,21,0,0,0,0,0,0,21,28,28,28,28,28
28,28,28,21,0,0,0,0,0,0,21,28,28,28,28,28
28,28,28,21,0,0,0,0,0,0,21,28,28,28,28,28
28,28,28,20,21,21,21,21,21,21,20,28,28,28,28,28
28,28,28,28,28,28,28,28,28,28,28,28,28,28,28,28
28,28,28,28,28,28,28,28,28,28,28,28,28,28,28,28
endlayer

layer
28,28,28,28,28,28,28,28,28,28,28,28,28,28,28,28
28,28,28,28,28,28,28,28,28,28,28,28,28,28,28,28
28,28,28,26,26,26,26,26,26,26,26,28,28,28,28,28
28,28,28,26,21,24,21,21,21,21,26,28,28,28,28,28
28,28,28,26,21,21,21,21,21,21,26,28,28,28,28,28
28,28,28,26,21,21,21,21,21,21,26,28,28,28,28,28
28,28,28,26,21,21,21,21,21,21,26,28,28,28,28,28
28,28,28,26,21,21,21,21,21,21,26,28,28,28,28,28
28,28,28,26,26,26,26,26,26,26,26,28,28,28,28,28
28,28,28,28,28,28,28,28,28,28,28,28,28,28,28,28
28,28,28,28,28,28,28,28,28,28,28,28,28,28,28,28
endlayer

layer
28,28,28,28,28,28,28,28,28,28,28,28,28,28,28,28
28,28,28,28,28,28,28,28,28,28,28,28,28,28,28,28
28,28,28,27,27,27,27,27,27,27,27,28,28,28,28,28
28,28,28,27,0,0,0,0,0,0,27,28,28,28,28,28
28,28,28,27,0,0,0,0,0,0,27,28,28,28,28,28
28,28,28,27,0,0,0,0,0,0,27,28,28,28,28,28
28,28,28,27,0,0,0,0,0,0,27,28,28,28,28,28
28,28,28,27,0,0,0,0,0,0,27,28,28,28,28,28
28,28,28,27,27,27,27,27,27,27,27,28,28,28,28,28
28,28,28,28,28,28,28,28,28,28,28,28,28,28,28,28
28,28,28,28,28,28,28,28,28,28,28,28,28,28,28,28
endlayer

